<?xml version="1.0"?>
<robot name="rv7frl_test_phys">

  <link name="world"/>

  <!-- Fixed world->base -->
  <joint name="rv7frl_world_to_base" type="fixed">
    <origin xyz="0 0 0" rpy="0 0 0" />
    <parent link="world" />
    <child link="rv7frl_base" />
  </joint>

  <!-- J1..J6 (same kinematics as your URDF) -->
  <joint name="rv7frl_joint_1" type="revolute">
    <axis xyz="0 0 1" />
    <limit lower="-4.188790" upper="4.188790" effort="529.68" velocity="5.026548" />
    <origin xyz="0 0 0" rpy="0 0 0" />
    <parent link="rv7frl_base" />
    <child link="rv7frl_shoulder" />
  </joint>

  <joint name="rv7frl_joint_2" type="revolute">
    <axis xyz="0 1 0" />
    <limit lower="-1.919862" upper="2.268928" effort="547.43" velocity="5.602507" />
    <origin xyz="0 0 0.4" rpy="0 0 0" />
    <parent link="rv7frl_shoulder" />
    <child link="rv7frl_upper_arm" />
  </joint>

  <joint name="rv7frl_joint_3" type="revolute">
    <axis xyz="0 1 0" />
    <limit lower="0.000000" upper="2.827433" effort="281.97" velocity="6.283185" />
    <origin xyz="0 0 0.435" rpy="0 0 0" />
    <parent link="rv7frl_upper_arm" />
    <child link="rv7frl_elbow" />
  </joint>

  <joint name="rv7frl_joint_4" type="revolute">
    <axis xyz="0 0 1" />
    <limit lower="-3.490659" upper="3.490659" effort="107.52" velocity="5.881760" />
    <origin xyz="-0.05 0 0" rpy="0 0 0" />
    <parent link="rv7frl_elbow" />
    <child link="rv7frl_forearm" />
  </joint>

  <joint name="rv7frl_joint_5" type="revolute">
    <axis xyz="0 1 0" />
    <limit lower="-2.094395" upper="2.094395" effort="51.84" velocity="7.853981" />
    <origin xyz="0 0 0.47" rpy="0 0 0" />
    <parent link="rv7frl_forearm" />
    <child link="rv7frl_wrist" />
  </joint>

  <joint name="rv7frl_joint_6" type="revolute">
    <axis xyz="0 0 1" />
    <limit lower="-6.283185" upper="6.283185" effort="25.20" velocity="12.566371" />
    <origin xyz="0 0 0.085" rpy="0 0 0" />
    <parent link="rv7frl_wrist" />
    <child link="rv7frl_hand_flange" />
  </joint>

  <joint name="rv7frl_hand_flange_to_default_tcp" type="fixed">
    <origin xyz="0 0 0" rpy="0 0 0" />
    <parent link="rv7frl_hand_flange" />
    <child link="rv7frl_default_tcp" />
  </joint>

  <!-- Optional payload link (m7/I7) -->
  <joint name="rv7frl_tcp_to_payload" type="fixed">
    <origin xyz="0 0 0" rpy="0 0 0"/>
    <parent link="rv7frl_default_tcp"/>
    <child link="rv7frl_payload"/>
  </joint>

  <!-- ================= Links with inertials ================= -->

  <link name="rv7frl_base">
    <inertial>
      <!-- s0 (mm): x=0.61 y=-31.52 z=34.99 -->
      <origin xyz="0.00061 -0.03152 0.03499" rpy="0 0 0"/>
      <mass value="14.0"/>
      <!-- I0 NOT PROVIDED in your table -> estimated (replace when you have CAD I0) -->
      <inertia ixx="0.125" ixy="0" ixz="0" iyy="0.125" iyz="0" izz="0.158"/>
    </inertial>
    <visual><origin xyz="0 0 0" rpy="0 0 0"/><geometry><mesh filename="package://melfa_description/meshes/rv7frl/base.STL"/></geometry></visual>
    <collision><origin xyz="0 0 0" rpy="0 0 0"/><geometry><mesh filename="package://melfa_description/meshes/rv7frl/base.STL"/></geometry></collision>
  </link>

  <link name="rv7frl_shoulder">
    <inertial>
      <!-- s1 (mm): x=-9.64 y=-76.72 z=145.46 -->
      <origin xyz="-0.00964 -0.07672 0.14546" rpy="0 0 0"/>
      <mass value="8.0"/>
      <!-- I1 (gmm^2 -> kgm^2) -->
      <inertia ixx="0.104" ixy="0.000268" ixz="-0.000575"
               iyy="0.0947" iyz="0.0298"
               izz="0.0387"/>
    </inertial>
    <visual><origin xyz="0 0 0" rpy="0 0 0"/><geometry><mesh filename="package://melfa_description/meshes/rv7frl/shoulder.STL"/></geometry></visual>
    <collision><origin xyz="0 0 0" rpy="0 0 0"/><geometry><mesh filename="package://melfa_description/meshes/rv7frl/shoulder.STL"/></geometry></collision>
  </link>

  <link name="rv7frl_upper_arm">
    <inertial>
      <!-- s2 (mm): x=-19.57 y=-39.57 z=32.65 -->
      <origin xyz="-0.01957 -0.03957 0.03265" rpy="0 0 0"/>
      <mass value="19.7"/>
      <!-- I2 -->
      <inertia ixx="0.712" ixy="-0.00235" ixz="0.0139"
               iyy="0.678" iyz="0.00522"
               izz="0.11"/>
    </inertial>
    <visual><origin xyz="0 0 0" rpy="0 0 0"/><geometry><mesh filename="package://melfa_description/meshes/rv7frl/upper_arm.STL"/></geometry></visual>
    <collision><origin xyz="0 0 0" rpy="0 0 0"/><geometry><mesh filename="package://melfa_description/meshes/rv7frl/upper_arm.STL"/></geometry></collision>
  </link>

  <link name="rv7frl_elbow">
    <inertial>
      <!-- s3 (mm): x=2.30 y=-0.40 z=207.26 -->
      <origin xyz="0.00230 -0.00040 0.20726" rpy="0 0 0"/>
      <mass value="4.6"/>
      <!-- I3 -->
      <inertia ixx="0.0195" ixy="-0.000627" ixz="0.00468"
               iyy="0.0203" iyz="0.00134"
               izz="0.0169"/>
    </inertial>
    <visual><origin xyz="0 0 0" rpy="0 0 0"/><geometry><mesh filename="package://melfa_description/meshes/rv7frl/elbow.STL"/></geometry></visual>
    <collision><origin xyz="0 0 0" rpy="0 0 0"/><geometry><mesh filename="package://melfa_description/meshes/rv7frl/elbow.STL"/></geometry></collision>
  </link>

  <link name="rv7frl_forearm">
    <inertial>
      <!-- s4 (mm): x=2.07 y=19.64 z=28.97 -->
      <origin xyz="0.00207 0.01964 0.02897" rpy="0 0 0"/>
      <mass value="5.8"/>
      <!-- I4 -->
      <inertia ixx="0.0805" ixy="-0.000043" ixz="-0.000256"
               iyy="0.0776" iyz="0.00076"
               izz="0.0121"/>
    </inertial>
    <visual><origin xyz="0 0 0" rpy="0 0 0"/><geometry><mesh filename="package://melfa_description/meshes/rv7frl/forearm.STL"/></geometry></visual>
    <collision><origin xyz="0 0 0" rpy="0 0 0"/><geometry><mesh filename="package://melfa_description/meshes/rv7frl/forearm.STL"/></geometry></collision>
  </link>

  <link name="rv7frl_wrist">
    <inertial>
      <!-- s5 (mm): x=0.12 y=0.00 z=-11.11 -->
      <origin xyz="0.00012 0.00000 -0.01111" rpy="0 0 0"/>
      <mass value="1.1"/>
      <!-- I5 -->
      <inertia ixx="0.00157" ixy="-0.0000127" ixz="0.0000143"
               iyy="0.00189" iyz="-0.0000626"
               izz="0.000873"/>
    </inertial>
    <visual><origin xyz="0 0 0" rpy="0 0 0"/><geometry><mesh filename="package://melfa_description/meshes/rv7frl/wrist.STL"/></geometry></visual>
    <collision><origin xyz="0 0 0" rpy="0 0 0"/><geometry><mesh filename="package://melfa_description/meshes/rv7frl/wrist.STL"/></geometry></collision>
  </link>

  <link name="rv7frl_hand_flange">
    <inertial>
      <!-- s6 (mm): x=0 y=0 z=0 -->
      <origin xyz="0 0 0" rpy="0 0 0"/>
      <mass value="0.2"/>
      <!-- I6 -->
      <inertia ixx="0.000147" ixy="0.0000000279" ixz="-0.000000931"
               iyy="0.000143" iyz="0"
               izz="0.0000969"/>
    </inertial>
    <visual><origin xyz="0 0 0" rpy="0 0 0"/><geometry><mesh filename="package://melfa_description/meshes/rv7frl/hand_flange.STL"/></geometry></visual>
    <collision><origin xyz="0 0 0" rpy="0 0 0"/><geometry><mesh filename="package://melfa_description/meshes/rv7frl/hand_flange.STL"/></geometry></collision>
  </link>

  <link name="rv7frl_default_tcp" />

  <link name="rv7frl_payload">
    <inertial>
      <!-- s7 (mm): x=0 y=0 z=0 -->
      <origin xyz="0 0 0" rpy="0 0 0"/>
      <mass value="7.0"/>
      <!-- I7 -->
      <inertia ixx="0.03" ixy="0" ixz="0"
               iyy="0.03" iyz="0"
               izz="0.0468"/>
    </inertial>
  </link>

</robot>

