<?xml version="1.0" ?>
<!-- =================================================================================== -->
<!-- |    This document was autogenerated by xacro from /home/melco/sho/proximity_check_mvp/src/melfa_description/urdf/rv7frl/rv7frl.urdf.xacro | -->
<!-- |    EDITING THIS FILE BY HAND IS NOT RECOMMENDED                                 | -->
<!-- =================================================================================== -->
<robot name="rv7frl">
  <!-- Use world link to fix robot -->
  <link name="world"/>
  <material name="white">
    <color rgba="1.0 1.0 1.0 1.0"/>
  </material>
  <joint name="rv7frl_world_to_base" type="fixed">
    <origin rpy="0 -0 0" xyz="0 0 0"/>
    <parent link="world"/>
    <child link="rv7frl_base"/>
    <dynamics damping="1.0" friction="1.0"/>
  </joint>
  <joint name="rv7frl_joint_1" type="revolute">
    <origin rpy="0 0 0" xyz="0 0 0"/>
    <parent link="rv7frl_base"/>
    <child link="rv7frl_shoulder"/>
    <axis xyz="0 0 1"/>
    <limit effort="50" lower="-4.188790" upper="4.188790" velocity="5.026548"/>
    <dynamics damping="1.0" friction="1.0"/>
  </joint>
  <joint name="rv7frl_joint_2" type="revolute">
    <origin rpy="0 0 0" xyz="0 0 0.4"/>
    <parent link="rv7frl_shoulder"/>
    <child link="rv7frl_upper_arm"/>
    <axis xyz="0 1 0"/>
    <limit effort="50" lower="-1.919862" upper="2.268928" velocity="5.602507"/>
    <dynamics damping="1.0" friction="1.0"/>
  </joint>
  <joint name="rv7frl_joint_3" type="revolute">
    <origin rpy="0 0 0" xyz="0 0 0.435"/>
    <parent link="rv7frl_upper_arm"/>
    <child link="rv7frl_elbow"/>
    <axis xyz="0 1 0"/>
    <limit effort="50" lower="0.000000" upper="2.827433" velocity="6.283185"/>
    <dynamics damping="1.0" friction="1.0"/>
  </joint>
  <joint name="rv7frl_joint_4" type="revolute">
    <origin rpy="0 0 0" xyz="-0.05 0 0"/>
    <parent link="rv7frl_elbow"/>
    <child link="rv7frl_forearm"/>
    <axis xyz="0 0 1"/>
    <limit effort="50" lower="-3.490659" upper="3.490659" velocity="5.881760"/>
    <dynamics damping="1.0" friction="1.0"/>
  </joint>
  <joint name="rv7frl_joint_5" type="revolute">
    <origin rpy="0 0 0" xyz="0 0 0.47"/>
    <parent link="rv7frl_forearm"/>
    <child link="rv7frl_wrist"/>
    <axis xyz="0 1 0"/>
    <limit effort="50" lower="-2.094395" upper="2.094395" velocity="7.853981"/>
    <dynamics damping="1.0" friction="1.0"/>
  </joint>
  <joint name="rv7frl_joint_6" type="revolute">
    <origin rpy="0 0 0" xyz="0 0 0.085"/>
    <parent link="rv7frl_wrist"/>
    <child link="rv7frl_hand_flange"/>
    <axis xyz="0 0 1"/>
    <limit effort="50" lower="-6.283185" upper="6.283185" velocity="12.566371"/>
    <dynamics damping="1.0" friction="1.0"/>
  </joint>
  <joint name="rv7frl_hand_flange-to-default_tcp" type="fixed">
    <origin rpy="0 0 0" xyz="0 0 0"/>
    <parent link="rv7frl_hand_flange"/>
    <child link="rv7frl_default_tcp"/>
    <dynamics damping="1.0" friction="1.0"/>
  </joint>
  <link name="rv7frl_base">
    <visual>
      <material name="white"/>
      <origin rpy="0 0 0" xyz="0 0 0"/>
      <geometry>
        <mesh filename="package://melfa_description/meshes/rv7frl/base.STL"/>
      </geometry>
    </visual>
    <collision>
      <origin rpy="0 0 0" xyz="0 0 0"/>
      <geometry>
        <mesh filename="package://melfa_description/meshes/rv7frl/base.STL"/>
      </geometry>
    </collision>
    <inertial>
      <mass value="0.4"/>
      <origin rpy="0 0 0" xyz="0.0 0.0 0.0"/>
      <inertia ixx="0.000443333156" ixy="0.0" ixz="0.0" iyy="0.000443333156" iyz="0.0" izz="0.0007199999999999999"/>
    </inertial>
  </link>
  <link name="rv7frl_shoulder">
    <visual>
      <material name="white"/>
      <origin rpy="0 0 0" xyz="0 0 0"/>
      <geometry>
        <mesh filename="package://melfa_description/meshes/rv7frl/shoulder.STL"/>
      </geometry>
    </visual>
    <collision>
      <origin rpy="0 0 0" xyz="0 0 0"/>
      <geometry>
        <mesh filename="package://melfa_description/meshes/rv7frl/shoulder.STL"/>
      </geometry>
    </collision>
    <inertial>
      <mass value="0.37"/>
      <origin rpy="0 0 0" xyz="0.0 0.0 0.0"/>
      <inertia ixx="0.00041008316929999996" ixy="0.0" ixz="0.0" iyy="0.00041008316929999996" iyz="0.0" izz="0.0006659999999999999"/>
    </inertial>
  </link>
  <link name="rv7frl_upper_arm">
    <visual>
      <material name="white"/>
      <origin rpy="0 0 0" xyz="0 0 0"/>
      <geometry>
        <mesh filename="package://melfa_description/meshes/rv7frl/upper_arm.STL"/>
      </geometry>
    </visual>
    <collision>
      <origin rpy="0 0 0" xyz="0 0 0"/>
      <geometry>
        <mesh filename="package://melfa_description/meshes/rv7frl/upper_arm.STL"/>
      </geometry>
    </collision>
    <inertial>
      <mass value="0.3393"/>
      <origin rpy="0 0 0" xyz="0.0 0.0 0.0"/>
      <inertia ixx="0.00037605734957699995" ixy="0.0" ixz="0.0" iyy="0.00037605734957699995" iyz="0.0" izz="0.0006107399999999999"/>
    </inertial>
  </link>
  <link name="rv7frl_elbow">
    <visual>
      <material name="white"/>
      <origin rpy="0 0 0" xyz="0 0 0"/>
      <geometry>
        <mesh filename="package://melfa_description/meshes/rv7frl/elbow.STL"/>
      </geometry>
    </visual>
    <collision>
      <origin rpy="0 0 0" xyz="0 0 0"/>
      <geometry>
        <mesh filename="package://melfa_description/meshes/rv7frl/elbow.STL"/>
      </geometry>
    </collision>
    <inertial>
      <mass value="0.1219"/>
      <origin rpy="0 0 0" xyz="0.0 0.0 0.0"/>
      <inertia ixx="0.00013510577929099998" ixy="0.0" ixz="0.0" iyy="0.00013510577929099998" iyz="0.0" izz="0.00021941999999999998"/>
    </inertial>
  </link>
  <link name="rv7frl_forearm">
    <visual>
      <material name="white"/>
      <origin rpy="0 0 0" xyz="0 0 0"/>
      <geometry>
        <mesh filename="package://melfa_description/meshes/rv7frl/forearm.STL"/>
      </geometry>
    </visual>
    <collision>
      <origin rpy="0 0 0" xyz="0 0 0"/>
      <geometry>
        <mesh filename="package://melfa_description/meshes/rv7frl/forearm.STL"/>
      </geometry>
    </collision>
    <inertial>
      <mass value="0.1219"/>
      <origin rpy="0 0 0" xyz="0.0 0.0 0.0"/>
      <inertia ixx="0.00013510577929099998" ixy="0.0" ixz="0.0" iyy="0.00013510577929099998" iyz="0.0" izz="0.00021941999999999998"/>
    </inertial>
  </link>
  <link name="rv7frl_wrist">
    <visual>
      <material name="white"/>
      <origin rpy="0 0 0" xyz="0 0 0"/>
      <geometry>
        <mesh filename="package://melfa_description/meshes/rv7frl/wrist.STL"/>
      </geometry>
    </visual>
    <collision>
      <origin rpy="0 0 0" xyz="0 0 0"/>
      <geometry>
        <mesh filename="package://melfa_description/meshes/rv7frl/wrist.STL"/>
      </geometry>
    </collision>
    <inertial>
      <mass value="0.1219"/>
      <origin rpy="0 0 0" xyz="0.0 0.0 0.0"/>
      <inertia ixx="0.00013510577929099998" ixy="0.0" ixz="0.0" iyy="0.00013510577929099998" iyz="0.0" izz="0.00021941999999999998"/>
    </inertial>
  </link>
  <link name="rv7frl_hand_flange">
    <visual>
      <material name="white"/>
      <origin rpy="0 0 0" xyz="0 0 0"/>
      <geometry>
        <mesh filename="package://melfa_description/meshes/rv7frl/hand_flange.STL"/>
      </geometry>
    </visual>
    <collision>
      <origin rpy="0 0 0" xyz="0 0 0"/>
      <geometry>
        <mesh filename="package://melfa_description/meshes/rv7frl/hand_flange.STL"/>
      </geometry>
    </collision>
    <inertial>
      <mass value="0.1219"/>
      <origin rpy="0 0 0" xyz="0.0 0.0 0.0"/>
      <inertia ixx="0.00013510577929099998" ixy="0.0" ixz="0.0" iyy="0.00013510577929099998" iyz="0.0" izz="0.00021941999999999998"/>
    </inertial>
  </link>
  <link name="rv7frl_default_tcp"/>
  <ros2_control name="rv7frl" type="system">
    <hardware>
      <plugin>fake_components/GenericSystem</plugin>
      <param name="state_following_offset">0.0</param>
    </hardware>
    <joint name="rv7frl_joint_1">
      <param name="initial_position">0.0</param>
      <command_interface name="position">
        <param name="min">-4.188790</param>
        <param name="max">4.188790</param>
      </command_interface>
      <state_interface name="position"/>
    </joint>
    <joint name="rv7frl_joint_2">
      <param name="initial_position">0.0</param>
      <command_interface name="position">
        <param name="min">-1.919862</param>
        <param name="max">2.268928</param>
      </command_interface>
      <state_interface name="position"/>
    </joint>
    <joint name="rv7frl_joint_3">
      <param name="initial_position">1.571</param>
      <command_interface name="position">
        <param name="min">0.0</param>
        <param name="max">2.827433</param>
      </command_interface>
      <state_interface name="position"/>
    </joint>
    <joint name="rv7frl_joint_4">
      <param name="initial_position">0.0</param>
      <command_interface name="position">
        <param name="min">-3.490659</param>
        <param name="max">3.490659</param>
      </command_interface>
      <state_interface name="position"/>
    </joint>
    <joint name="rv7frl_joint_5">
      <param name="initial_position">1.571</param>
      <command_interface name="position">
        <param name="min">-2.094395</param>
        <param name="max">2.094395</param>
      </command_interface>
      <state_interface name="position"/>
    </joint>
    <joint name="rv7frl_joint_6">
      <param name="initial_position">0.0</param>
      <command_interface name="position">
        <param name="min">-6.283185</param>
        <param name="max">6.283185</param>
      </command_interface>
      <state_interface name="position"/>
    </joint>
  </ros2_control>
</robot>
